Workbook

Sheet MDM vs IDF
A1: MDM Gestión | E1: IDF | M1: MDM_Preguntas Gobierno abierto y transparencia | S1: IDI
A2: Variable | B2: Fuente | C2: Comentario | E2: El Índice de Desempeño Fiscal es una medición del desempeño de la gestión financiera de las ET que da cuenta de la sostenibilidad financiera a la luz de la viabilidad fiscal, la capacidad de generación de recursos propios, el endeudamiento, los niveles de inversión y la capacidad de gestión financiera en los municipios y departamentos del país. Su objetivo es medir la gestión fiscal de las entidades territoriales con el fin de identificar buenas prácticas en el manejo de las finanzas públicas y fortalecer la asistencia técnica territorial. Escala de 0 a 100 puntos, donde valores cercanos a 0 denotan un bajo desempeño fiscal, y valores cercanos a 100 indican que la entidad logró en conjunto, buenos resultados ANTIGUA METODOLOGÍA Indicador sintético con seis indicadores de gestión financiera a partir de un promedio simple que se encuentra en una en: • Autofinanciación de los gastos de funcionamiento: capacidad para cubrir el gasto de funcionamiento de la administración central con las rentas de libre destinación (Ley 617 de 2000). • Respaldo del servicio de la deuda: capacidad para respaldar el servicio de la deuda con los ingresos percibidos (servicio de la deuda/ingresos disponibles). • Dependencia de las transferencias de la Nación y Regalías: (100-((SGP-SGR+otras transferencias)/ingresos totales))). • Generación de Recursos Propios: ingresos tributarios/ingresos corrientes. • Magnitud de la Inversión: gasto total en inversión/gastos totales. • Capacidad de Ahorro: ahorro corriente/ ingresos corrientes. NUEVA METODOLOGÍA (Toman las capacidades inciales de referencia de grupos) Cuenta con 2 dimensiones de calificación. - Resultados Fiscales (80%): Promedio simple de los indicadores por temáticas: • Dependencia de las Transferencias: SGP y otras/ ingresos total (20%): El indice premia que las ET no dependas de las transferencias para su desarrollo • Inversión: Formación Bruta de Capital Fijo/ Gasto de Inversión (20%): premia el gasto de las inversiones que tienen retorno a futuro, tiene en cuenta los datos de los otros municipios • Endeudamiento: Pasivos/ activos (20%): premia las ET que tienen mayor respaldo para el pago de sus pasivos • Medidas de Déficit o Superávit: 1) Ahorro corriente/ Ingreso corriente, premia que se puedan liberar excedentes 2) Balance Primario/Ingresos Totales + Desembolsos: 20%. se permia que haya un equilibrio - Gestión Financiera Territorial (20%): Promedio simple de los indicadores + Bonificaciones: • Capacidad de programación y ejecución de ingresos: Para ingresos propios: Recaudo efectivo/Presupuesto inicial (o programación): • Capacidad de ejecución de inversión: Para inversión: Pagos/Compromisos • Cumplimiento límites de la Ley 617 de 2000 (holgura): Límite Ley 617- Gastos de funcionamiento/Ingresos corrientes de libre destinación. Otorga dos bonos: • Bonificación de esfuerzo propio: % crecimiento Tributarios + No Tributarios en dos vigencias (si por dos vigencias han tenido crecimiento positivo, se le da el bono) • Bonificación Actualización Catastral: 2 puntos en gestión por actualización Nota: tiene en cuenta las categorías de las capacidades iniciales para saber con quien compararse. Que vigencia tienen? la referencia de los grupos se incluye dentro del calculo de IDF? No Los que estan en morado es por que dependen de la calificación de los otros municipios | M2: No. | N2: Pregunta | O2: Tipo Respuesta
A3: * Movilización de recursos | M3: SERVICIO AL CIUDADANO | Q3: Código política | R3: Política | S3: Código pregunta | T3: Enunciado pregunta | U3: Opción de respuesta
A4: 1. (Ingresos tibutarios y no tributarios- recaudo por instrumentos OT*)/ población *recaudo por concepto de Impuesto Predial, Delineación Urbana, Valorización y Plusvalía | B4: Operaciones Efectivas de Caja-OEC (DNP), reportes CUIPO del CHIP y DANE | C4: Se estaría dejando de lado los ingresos por industria y comercio, sobretasa a la gasolina, entre otros (deguello, consumo de licores, tx de registro) | M4: 1 | N4: ¿La Entidad cuenta con procesos o procedimientos de servicio al ciudadano documentados e implementados (peticiones, quejas, reclamos y denuncias, trámites y servicios)? | O4: • SI • NO | Q4: SEC | R4: Servicio ciudadano | S4: SEC216 | T4: El formulario de Peticiones, Quejas, Reclamos, Sugerencias y Denuncias (PQRSD) dispuesto en el Menú de Atención y Servicios a la Ciudadanía a través del sitio web, contó con las siguientes condiciones técnicas: | U4: Mensaje de confirmación de recibido por la entidad Validación de campos mediante la que se alertó al ciudadano sobre errores o falta información en el diligenciamiento del formulario, de forma visible y accesible para todas las personas Mecanismo para que los correos electrónicos remitidos de manera automática no se categorizaran como NO deseados o SPAM Mecanismos de seguimiento en línea para que el ciudadano verificara el estado de respuesta de su petición, queja, reclamo, sugerencia y denuncia (PQRSD) Mecanismos para informar al ciudadano el motivo y las opciones para hacer nuevamente su solicitud, en caso de que el sistema presentara errores durante el diligenciamiento del formulario Vinculó las solicitudes de información pública como una tipología en el sistema de peticiones, quejas, reclamos, sugerencias y denuncias (PQRSD), para gestionarlas y hacerles seguimiento Opción para ser diligenciado y enviado a través de dispositivos móviles Medidas de seguridad digital y de la información, acorde a los lineamientos del anexo 3 de la resolución 1519 de 2020 Ninguna de las anteriores
A5: 2. Recuado total por instrumentos de OT (predial, delimintación urbana, valorización, plusvalia)/ población | B5: Reportes CUIPO del CHIP y DANE | J5: Hay tres momentos del gasto: i) compromiso, ii) obligación, iii) pago | M5: PARTICIPACIÓN Y RENDICIÓN DE CUENTAS - ESTRATÉGICO | Q5: PCI | R5: Participación ciudadana | S5: PCI206 | T5: Qué tipo de acciones formuló e implementó la entidad en el proceso de rendición de cuentas durante la vigencia evaluada: | U5: Acciones de información para fortalecer la transparencia Jornadas de diálogo para la evaluación ciudadana de la gestión Acciones de responsabilidad para asumir compromisos de mejora institucional con la ciudadanía Acciones de articulación en nodos en el marco del Sistema Nacional de Rendición de Cuentas Acciones de información, diálogo y responsabilidad para la construcción de paz Ninguna de las anteriores
A6: 3. Inversión financiada con recursos propios/ inversión total del municipio | B6: Operaciones Efectivas de Caja-OEC (DNP) y reportes CUIPO del CHIP | M6: 1 | N6: ¿En el Plan de Acción Anual está incluída la estrategia de Rendición de Cuentas? | O6: • SI • NO
A7: * Ejecución de recursos | M7: 2 | N7: ¿La Entidad publica los resultados de la consulta pública del proceso de rendición de cuentas y de la regulación identificando las prioridades y comentarios establecidos por los ciudadanos? | O7: • SI • NO | Q7: PCI | R7: Participación ciudadana | S7: PCI208 | T7: ¿Cuáles de los siguientes medios utilizó la entidad, durante la vigencia evaluada, para divulgar la información de los espacios de participación ciudadana y/o rendición de cuentas? | U7: Mensajes de texto Redes sociales Radio, televisión y otros medios audiovisuales Página web Correo electrónico Carteleras, boletines, folletos u otros recursos físicos Reuniones presenciales o virtuales Otro. ¿Cuál? Ninguno de los anteriores
A8: 1. Recursos obligados en la vigencia relacionados con los sectores de desarrollo económico/ Recursos apropiados en la vigencia relacionados con los sectores de desarrollo económico * Obligaciones contraidas o compromisos Las apropiaciones son autorizaciones máximas de gasto que el Congreso de la República aprueba para ser comprometidas durante la vigencia fiscal respectiva. Apropiación= programación | B8: Reportes CUIPO | C8: El IDF mide también la "ejecución", pero de forma diferente: capacidad de programación y ejecución de ingresos, y capacidad de ejecución de inversión. Estos son ejecución del gasto | Q8: PCI | R8: Participación ciudadana | S8: PCI209 | T8: Seleccione los temas sobre los cuáles la entidad publicó y divulgó información en los espacios de participación ciudadana y/o rendición de cuentas, durante la vigencia evaluada: | U8: Diagnóstico participativo Formulación participativa de políticas, planes, programas, proyectos y servicios Consulta ciudadana sobre normas, políticas, programas, proyectos o trámites Plan Anticorrupción y de Atención al Ciudadano Colaboración e innovación abierta Rendición de cuentas sobre la gestión institucional, sus resultados, la garantía de derechos y el cumplimiento de ODS Rendición de cuentas sobre implementación del acuerdo de paz Control social a la gestión pública Los aspectos que dan cuenta del cumplimiento en gestión documental y administración de archivos Ninguno de los anteriores
A9: 2. Recursos obligados en la vigencia relacionados con los sectores de desarrollo social/ Recursos apropiados en la vigencia relacionados con los sectores de desarrollo social | B9: Reportes CUIPO | M9: ANTICORRUPCIÓN | S9: Otras preguntas de rendición de cuentas: PCI207- El nivel de satisfacción frente a los espacios de rendición de cuentas de la entidad, como resultado de la medición de la experiencia ciudadana, para la vigencia evaluada fue:, PCI210. Seleccione las acciones de diálogo implementadas por la entidad durante la vigencia evaluada para la rendición de cuentas:, PCI212- Seleccione los grupos de valor que participaron durante la vigencia evaluada en las acciones de diálogo presenciales y/o virtuales para la rendición de cuentas:, PCI213- Para determinar si hubo mejora en la gestión institucional derivado de la implementación de las acciones de participación ciudadana y/o rendición de cuentas, la entidad:, SYE218- La entidad utilizó la información generada en los ejercicios de rendición de cuentas y evaluación de la percepción ciudadana para:
A10: 3. Recursos obligados en la vigencia relacionados con los sectores de otros sectores/ Recursos apropiados en la vigencia relacionados con los sectores de otros sectores | B10: Reportes CUIPO | M10: 1 | N10: Indique los componentes incluídos en el Plan Anticorrupción y de Atención al Ciudadano | O10: • Rendición de cuentas • Servicio al Ciudadano • Racionalización de trámites | Q10: TRA | R10: Transparencia | S10: TRA206 | T10: Seleccione los componentes del Plan Anticorrupción y de Atención al Ciudadano de la entidad a los cuales se les hizo seguimiento: | U10: Mapa de riesgos de corrupción y las medidas para mitigarlos Racionalización de Trámites Rendición de cuentas Participación ciudadana Servicio al ciudadano Transparencia y acceso a la Información
A11: 4. Promedio simple del indicador de eficiencia de todos los proyectos de regalías ejecutados por la entidad en la vigencia | B11: Reportes CUIPO | C11: Por qué solo regalías? | M11: GESTIÓN DOCUMENTAL | S11: Otras preguntas sobre anticorrupción: TRA201- ¿La entidad elaboró el Plan Anticorrupción y de Atención al Ciudadano, para la vigencia 2023?, TRA203- Seleccione los grupos de valor y otras instancias que fueron consultados para la elaboración del Plan Anticorrupción y de Atención al Ciudadano:, TRA204- ¿Cuáles mecanismos utilizó la entidad para dar a conocer los lineamientos establecidos en el Plan Anticorrupción y de Atención al Ciudadano a sus grupos de valor y a la ciudadanía?, TRA205, La entidad realizó monitoreo al Plan Anticorrupción y de Atención al Ciudadano:
A12: *Gobierno abierto y transparencia | N12: Implementación de la Ley de Archivos (Ley 594 de 2000)
A13: 1. Organización de la información: ¿Su municipio cuenta con Tablas de Retención Documental (TRD) elaboradas y aprobadas?, ¿su municipio aplica las Tablas de Retención Documental TRD aprobadas?, ¿Su municipio actualiza las Tablas de Retención Documental TRD? ¿Cada cuántos meses? | B13: Cuestionario - Las preguntas se suben en el aplicativo GESTIONWEB. - Generalmente hacia el mes de abril sale la circular que se socializa a las ET para que tengan el cronograma de fechas para el cargue de la información. -Generalmente se deja abierto el sistema 1 mes y medio para el reporte. | C13: IDI: Tiene en cuenta D5 Información y Comunicación, POLÍTICA 15 Transparencia, Acceso a la Información y lucha contra la Corrupción, POLÍTICA 16 Gestión Documental, i48Índice de Transparencia y Acceso a la Información Pública. Dentro de las preguntas que se les hace, incluyen todo el detalle sobre las Tablas de retención documental | J13: Formación bruta de capital fijo usa las dotaciones iniciales del MDM | M13: 1 | N13: Su municipio cuenta con Tablas de Retención Documental (TRD) elaboradas y aprobadas? | O13: • SI • NO | Q13: GDO | R13: Gestión documental | S13: GDO211 | T13: Con respecto a las Tablas de Retención Documental - TRD, la entidad: | U13: Analizó si cuenta con series y subseries documentales relativas a derechos humanos, memoria histórica y conflicto armado, en el proceso de valoración Identificó en las TRD los documentos audiovisuales (video, audio, fotográficos) en cualquier soporte y medio (analógico, electrónico) que hacen parte de las series y subseries documentales Identificó en las TRD los tipos documentales en formatos electrónicos, conforme a los flujos y procedimientos para la producción documental de la entidad Las tiene actualizadas, aprobadas y convalidadas conforme a la estructura orgánica vigente de la entidad Las implementó para efectuar las transferencias documentales primarias Las implementó para efectuar las transferencias documentales secundarias Las implementó para efectuar el proceso de eliminación documental, conforme al procedimiento establecido en la normatividad vigente Cuenta con las TRD, pero no se aplican No tiene TRD. Explique la razón:
A14: 2. Rendición de cuentas: ¿En el Plan de Acción Anual está incluida la estrategia de Rendición de Cuentas?, ¿La Entidad pública los resultados de la consulta del proceso de rendición de cuentas, identificando las prioridades establecidas por los ciudadanos? *Índice de Gestión de Proyectos de Regalías IGPR: refleja la eficiencia en la gestión de recursos de los proyectos de regalías que ejecutó la entidad para la vigencia | B14: Cuestionario | C14: IDI: Tiene en cuenta D2 Direccionamiento Estratégico y Planeación, D7 Control Interno Dentro de las preguntas que se les hace, se especifica el tema de rendición de cuentas | M14: 2 | N14: Para la gestión documental, ¿su municipio aplica las Tablas de Retención Documental TRD aprobadas? | O14: • SI • NO
A15: 3. Atención al ciudadano: ¿La Entidad cuenta con procesos o procedimientos de servicio al ciudadano documentados e implementados (peticiones, quejas, reclamos y denuncias, trámites y servicios)?, ¿Incluyó el componente de Servicio al Ciudadano en el Plan Anticorrupción y de Atención al Ciudadano? | B15: Cuestionario | C15: IDI: tienen POLÍTICA 15 Transparencia, Acceso a la Información y lucha contra la Corrupción, i47Gestión de Riesgos de Corrupción | M15: 3 | N15: Su municipio actualiza las Tablas de Retención Documental TRD? Cada cuántos meses? | O15: • - SI - NO • Número entero
A16: * Ordenamiento territorial
A17: 1. (Recaudo predial/ avalúo de los predios en la vigencia) X 1000 | B17: Reportes del CUIPO e IGAC
A18: 2. Número de instrumentos de ordenamiento territorial que usa la Entidad Territorial | B18: Reportes del CUIPO
A20: https://colaboracion.dnp.gov.co/CDT/Desarrollo%20Territorial/Gu%C3%ADa%20de%20orientaciones%202022%20PROCESO%20MDET.pdf
A24: MDM | C24: MDD
A54: MDD- resultados
A55: Nombre de la variable | B55: Descripción | C55: Tipo | D55: Fuente | E55: Vigencia
A56: ID | B56: Identificador de la entidad en un año específico | C56: Número | D56: No aplica | E56: No aplica
A57: año | B57: Vigencia de la medición | C57: Número | D57: No aplica | E57: No aplica
A58: cdpto | B58: Código DANE de la entidad | C58: Número | D58: DANE | E58: No aplica
A59: ndpto | B59: Nombre de la entidad | C59: Texto | D59: DANE | E59: No aplica
A60: g11_itnt | B60: Ingresos tributariso y no tributarios per cápita | C60: Moneda | D60: OEC - DNP | E60: 2020 - 2022
A61: g12_recpropios | B61: Participación de los recursos propios en la inversión | C61: Porcentaje | D61: CUIPO - OEC - DNP | E61: 2020 - 2022
A62: g13_deptrans | B62: Dependencia a las transferencias | C62: Porcentaje | D62: CUIPO - OEC - DNP | E62: 2020 - 2022
A63: g21_porc_de | B63: Porcentaje de ejecución sectores de desarrollo económico | C63: Porcentaje | D63: CUIPO | E63: 2020 - 2022
A64: g22_porc_ds | B64: Porcentaje de ejecución sectores de desarrollo social | C64: Porcentaje | D64: CUIPO | E64: 2020 - 2022
A65: g23_porc_o | B65: Porcentaje de ejecución otros sectores | C65: Porcentaje | D65: CUIPO | E65: 2020 - 2022
A66: g24_igpr | B66: Indicador de eficiencia del IGPR | C66: Número | D66: IGPR - DNP | E66: 2020 - 2022
... A112: mdd | B112: Puntaje Medición de Desempeño Departamental | C112: Número | D112: Cálculos propios - DNP | E112: 2020 - 2022
A117: IPM | F117: NBI
A118: Condiciones educativas del hogar (0.2) | B118: Analfabetismo (0.1) | C118: Escolaridad promedio de las personas de 15 años y más del hogar | F118: Componente vivienda | G118: Materiales de construcción utilizados en piso, paredes y techo | H118: Son consideradas como no adecuadas para el alojamiento de personas, las viviendas móviles o ubicadas en refugios naturales o bajo puentes, o sin paredes, con paredes de tela o de materiales de desecho, o con pisos de tierra, arena o barro. | J118: IPM: 5 PRIVACIONES NBI: 2 PRIVACIONES
B119: Bajo logro educativo (0.1) | C119: Porcentaje de personas del hogar de 15 años y más que no saben leer y escribir | F119: Componente Servicios | G119: evalúa el acceso a condiciones sanitarias mínimas | H119: a) Disponibilidad de agua potable
A120: Condiciones de la niñez y juventud (0.2) | B120: Barreras a servicios para cuidado de la primera infancia (0.05) | C120: Proporción de niños de cero a cinco años en el hogar sin acceso a servicios de salud o que pasa la mayor parte del tiempo con su padre o madre en el trabajo, en casa solo, o está al cuidado de un pariente menor de 18 años | H120: b) Tipo de sistema de eliminación de excretas
B121: Inasistencia escolar (0.05) | C121: Proporción de niños, niñas y adolescentes (NNA) entre 6 y 16 años en el hogar que no asisten al colegio | F121: Componente Hacinamiento | G121: Niveles de ocupación de la vivienda | H121: i) Número de personas en el hogar ii) Número de cuartos de la vivienda
B122: Rezago escolar (0.05) | C122: Proporción de NNA (7-17 años) dentro del hogar con rezago escolar (según la norma nacional) | F122: Componente Inasistencia | G122: Asistencia de los niños en edad escolar a un establecimiento educativo | H122: i) Edad de los miembros del hogar ii) Asistencia a un establecimiento educativo
...

Sheet Paso a paso
A1: MUNICIPIOS
A2: Paso 1 | B2: Calculo de variables
B3: Promedio IDF 4 años
B4: Promedio IDI 4 años
A5: Paso 2 | B5: Cálculo IC
B6: Promedio IDF e IDI 4 años
A7: Paso 3 | B7: Calculo IDD e IDDr
B8: IDD (viene estandarizado) | C8: Rango: 0- 100
B9: IDDr | C9: Rango: 0- 100
B10: Cálculo cortes de jenks IDDr (la categoría 1 corresponde a los mun con mayor IDDr, que significa adecuado- menor distancia, mayor densidad) | C10: 5 cortes
B11: Definir las categorías de cada municipio con el IDDr y los cortes de jenks IDDr | C11: 5 categorías
A12: Paso 4 | B12: Calculo ponderador (no tiene en cuenta las categorías especiales)
B13: Promedio de IC teniendo en cuenta los cortes de jenks IDDr
B14: Promedio de IDDr teniendo en cuenta los cortes de jenks IDDr
B15: Calculo: prom IDDr/prom IC por categorías de IDDr
A16: Paso 5 | B16: Calculo IC ponderado
B17: Se asigna el ponderador por municipio según categorías (5) de IDDr | C17: 5 tipologías
B18: Se calcula el producto entre IC y el ponderador= Icpond
B19: Se estandariza el ICpond
B20: Se calculan cortes naturales de jenks (5) (la tipología 1 muestra los mun con mayor ICpond)
B21: Se define la tipología de Icpond de acuerdo a los cortes naturales
A23: DEPARTAMENTOS
A24: Paso 1 | B24: Calculo de variables
B25: Promedio IDF 4 años
B26: Promedio IDI 4 años
A27: Paso 2 | B27: Cálculo IC
B28: Promedio IDF e IDI 4 años
A29: Paso 3 | B29: Calculo IDD e IDDr
B30: Promedio departamental del IDD municipal (viene estandarizados)
B31: Estandarización del Promedio departamental del IDD municipal | C31: Rango: 0- 100
B32: Promedio departamental del IDDr municipal
B33: Estandarización del promedio departamental del IDDr municipal | C33: Rango: 0- 100 | D33: Nota: da igual si se toma el promedio departamental del IDD, se voltea (con máximo), y se cálculo el Z
B34: Cálculo cortes de jenks IDDr (la categoría 1 corresponde a los mun con mayor IDDr, que significa adecuado- menor distancia, mayor densidad) | C34: 3 cortes
B35: Definir las categorías de cada departamento con el IDDr y los cortes de jenks IDDr | C35: 3 categorías
A36: Paso 4 | B36: Calculo ponderador
B37: Promedio de IC teniendo en cuenta los cortes de jenks IDDr
B38: Promedio de IDDr teniendo en cuenta los cortes de jenks IDDr
B39: Calculo: prom IDDr/prom IC por categorías de IDDr
A40: Paso 5 | B40: Calculo IC ponderado
B41: Se asigna el ponderador por municipio según categorías (3) de IDDr
...

Sheet Diccionario2026
A1: Tipo | B1: Variables | C1: Direccionalidad | D1: Año | E1: Nivel territorial | F1: Definición | G1: Fuente
A2: Capacidades | B2: Índice de Desempeño Institucional | C2: Positivo | D2: 2021-2024 Promedio Móvil | E2: Municipal, distrital y departamental | F2: Es una operación estadística que mide anualmente la gestión y desempeño de las entidades públicas, proporcionando información para la toma de decisiones en materia de gestión. La meta del Plan Nacional de Desarrollo es mejorar en el cuatrienio el IDI en 10 puntos orden nacional y 5 puntos orden territorial. El IDI se presenta en una escala de 0 a 100, siendo 100 el máximo puntaje a lograr. Dimensiones: i) Talento Humano: Mide la capacidad de la entidad pública de gestionar adecuadamente su talento humano de acuerdo con las prioridades estratégicas de la entidad, las normas que les rigen en materia de personal y la garantía del derecho fundamental al diálogo social y a la concertación. ii) Direccionamiento Estratégico y Planeación: Mide la capacidad de la entidad pública de definir la ruta estratégica que guiará su gestión institucional con miras a garantizar los derechos, satisfacer las necesidades y solucionar los problemas de los ciudadanos destinatarios de sus productos y servicios, así como fortalecer la confianza ciudadana y la legitimidad. iii) Gestión para Resultados con Valores: Mide la capacidad de la entidad pública de ejecutar actividades que la conduzcan a lograr los resultados propuestos y a materializar las decisiones plasmadas en su planeación institucional, en el marco de los valores del servicio público; así mismo, capacidad para mantener una constante y fluida interacción con la ciudadanía de manera transparente y participativa, prestando un servicio de excelencia y facilitando la garantía del ejercicio de los derechos ciudadanos, a través de la entrega efectiva de productos, servicios e información. iv) Evaluación de Resultados: Mide la capacidad de la entidad pública de conocer de manera permanente los avances en su gestión y la consecución efectiva de los resultados planteados con la oportunidad, cantidad y calidad esperadas, e implementar acciones para mitigar los riesgos que la desvían del cumplimiento de sus objetivos y metas; Así mismo, el compromiso de la entidad para identificar aciertos y desaciertos en su gestión y promover acciones de mejora para superarlos. v) Información y Comunicación: adecuado flujo de información interna y externa, gestionar eficazmente los documentos que la soportan y mantener canales de comunicación acordes con sus capacidades organizacionales y con lo previsto en la Ley de Transparencia y Acceso a la Información. vi) Gestión del conocimiento: Mide la capacidad de la entidad pública de implementar acciones, mecanismos o instrumentos orientados a identificar, generar, capturar, transferir, apropiar, analizar, difundir y preservar el conocimiento para fortalecer a las entidades públicas, facilitar procesos de innovación y mejorar la prestación de productos y servicios a los grupos de valor. vii) Control Interno: contar con una serie de elementos clave de la gestión, cuyos controles asociados son evaluados de forma permanente, con niveles de autoridad y responsabilidad definidos. | G2: Función Pública- Medición del Desempeño Institucional Periodicidad: Anual Último año con información: 2024
A3: Capacidades | B3: Índice d​e Desempeño Fiscal | C3: Positivo | D3: 2021-2024 Promedio Móvil | E3: Municipal, distrital y departamental | F3: El Índice de Desempeño Fiscal es una medición del desempeño de la gestión financiera de las entidades territoriales que da cuenta de la sostenibilidad financiera a la luz de la viabilidad fiscal, la capacidad de generación de recursos propios, el endeudamiento, los niveles de inversión y la capacidad de gestión financiera en los municipios y departamentos del país. Su objetivo es medir la gestión fiscal de las entidades territoriales con el fin de identificar buenas prácticas en el manejo de las finanzas públicas y fortalecer la asistencia técnica territorial. Se encuentra en una escala de 0 a 100 puntos, donde valores cercanos a 0 denotan un bajo desempeño fiscal, y valores cercanos a 100 indican que la entidad logró en conjunto, buenos resultados en la medición. Cuenta con dos dimensiones de calificación: i) Resultados Fiscales (80%): Promedio simple de los indicadores por temáticas: • Dependencia de las Transferencias: SGP y otras/ ingresos total (20%): El índice premia que las ET no dependas de las transferencias para su desarrollo • Inversión: Formación Bruta de Capital Fijo/ Gasto de Inversión (20%): premia el gasto de las inversiones que tienen retorno a futuro, tiene en cuenta los datos de los otros municipios • Endeudamiento: Pasivos/ activos (20%): premia las ET que tienen mayor respaldo para el pago de sus pasivos • Medidas de Déficit o Superávit: 1) Ahorro corriente/ Ingreso corriente, premia que se puedan liberar excedentes 2) Balance Primario/Ingresos Totales + Desembolsos: 20%. se permia que haya un equilibrio ii) Gestión Financiera Territorial (20%): Promedio simple de los indicadores + Bonificaciones: • Capacidad de programación y ejecución de ingresos: Para ingresos propios: Recaudo efectivo/Presupuesto inicial (o programación) • Capacidad de ejecución de inversión: Para inversión: Pagos/Compromisos • Cumplimiento límites de la Ley 617 de 2000 (holgura): Límite Ley 617- Gastos de funcionamiento/Ingresos corrientes de libre destinación. Otorga dos bonos: • Bonificación de esfuerzo propio: % crecimiento Tributarios + No Tributarios en dos vigencias (si por dos vigencias han tenido crecimiento positivo, se le da el bono) • Bonificación Actualización Catastral: 2 puntos en gestión por actualización | G3: DNP- Índice d​e Desempeño Fiscal territorial Periodicidad: anual Último año con información: 2024
A4: Variable previa para el ponderador | B4: Índice de Distancias y Densidades (IDD) | C4: Negativo | D4: 2025 | E4: Municipal, distrital y departamental | F4: Municipal: IDD_m= Ln (tiempos de viaje/densidad poblacional^2) Tiempos de viaje a las ciudades más cercanas clasificadas por número de población: A. 1.000 a 2.000 habitantes: 44 B. 2.000 a 4.000 habitantes: 16 C. 4.000 a 1.000.000 habitantes: 13 D. Mayor a 1.000.000 habitantes: 5 (Bogotá, Cali, Medellín, Barranquilla, Cartagena) Una vez calculado el IDD_m se estandariza utilizando la siguiente fórmula: Z_IDD_m= 0.1+[(IDD_m-Min_IDD)/(Max_IDD-Min_IDD)]*(1-0.1) Donde, m: municipios. IDD: es el valor original de la variable IDD. Min_IDD: valor mínimo observado del IDD. Max_IDD: valor máximo observado del IDD. Z_IDD_m: valor estandarizado, transformado al rango [0.1, 1]. Departamental: Promedio del nivel municipal Se encuentra en una escala de 0,1 a 1 puntos, donde valores cercanos a 0 indican que son territorios con alta conectividad y densidad poblacional, y valores cercanos a 1 baja conectividad y densidad poblacional. | G4: Elaboración propia con base en la metodología del PNUD (2011) Proyecciones poblacionales DANE 2024 Calculo de tiempos de viaje 2025 Periodicidad: No definida Último año con información: 2025
A5: Ponderador final | B5: Índice de Distancias y Densidades invertido (IDDr) | C5: Positivo | D5: 2025 | E5: Municipal, distrital y departamental | F5: IDDr_m = max ( IDD)- Z_IDD_m El IDDr se presenta en una escala de 0 a 1, donde un valor de 0.1 indica que el municipio presenta mayores tiempos de desplazamiento hacia los municipios más poblados y una menor densidad poblacional; es decir, se trata de un territorio con mayores características de ruralidad. | G5: Elaboración propia Periodicidad: No definida Último año con información: 2025
A6: Variables de contraste | B6: Proporción territorial de áreas de protección ambiental y ecosistemas estratégicos (AA) | C6: - | D6: 2025 / 2017 | E6: Municipal, distrital y departamental | F6: %AA_m= áreas protegidas y ecosistemas estratégicos_m/ área total del municipio_m donde, %AA_m: porcentaje de áreas protegidas y ecosistemas estratégicos en relación con el área total de la entidad territorial. Áreas protegidas y ecosistemas estratégicos_m: Cruce de la información de las capas geográficas del Registro Único Nacional de Áreas Protegidas (RUNAP) del año 2025 y Registro de Ecosistemas y Áreas Ambientales (REAA) del año 2017, áreas interceptadas y calculadas geográficamente. Áreas total_m: área correspondiente a cada polígono identificado como entidades territoriales, en hectáreas y calculada geográficamente. m: entidad territorial RUNAP: Se incluyen todas las categorías: a) Parque nacional b) Reserva natural (es diferente a reservas de la sociedad civil) c) Área natural única d) Santuario de flora: área dedicada a preservar especies o comunidades vegetales e) Santuario de fauna: área dedicada a preservar especies o comunidades de animales silvestres f) Vía parque: faja de terreno con carretera, que posee bellezas panorámicas singulares o valores naturales o culturales, conservada para fines de educación y esparcimiento”. (a-f_ administrados por la Nación). g) Parques Naturales Regionales (no está incluida en el artículo 329 pero en la Sentencia de la C- 598/10 se pone en el mismo nivel de los Parques Nacionales Naturales)- (Administrados por la CAR) h) áreas de recreación i) distritos de conservación de suelos j) distritos nacionales de manejo integrado k) distritos regionales de manejo integrado l) reserva natural de la sociedad civil m) reservas forestales protectoras nacional n) reservas forestales protectoras regionales REAA: Se incluyen todas las categorías: Páramos, Humedales RAMSAR, Bosque Seco Tropical, Manglares, Pastos Marinos, Arrecifes coralinos, Reservas Forestales de Ley 2 de 1959 (Zona Tipo A), Áreas Susceptibles a Procesos de Restauración Ecológica, Áreas de proyectos Bosques de Paz orientados a la restauración ambiental y reconciliación de víctimas. | G6: Ministerio de Ambiente y Desarrollo Sostenible Periodicidad: RUNAP se actualiza constantemente (ej. cuando hay una actualización de límites, reservas de la sociedad civil) pero sin una periodicidad definida. REAA no se tiene información de cuándo será actualizado. Último año con información: RUNAP 2025, REAA 2017
A7: Variables de contraste | B7: Proporción territorial de área de territorios étnicos (ATE) | C7: - | D7: 2025 | E7: Municipal, distrital y departamental | F7: %ATE_m= área de territorios étnicos_m/ área total de la entidad territorial_m %ATE_m: porcentaje de territorios étnicos en relación con el área total de la entidad territorial. Áreas territorios étnicos_m: área correspondiente a los polígonos identificados como territorios étnicos, en hectáreas y calculada geográficamente para cada entidad territorial. Abarca las áreas de los resguardos indígenas legamente constituidos y las tierras colectivas tituladas a las comunidades NARP de acuerdo con la información oficial de la Agencia Nacional de Tierras. Áreas total_m: área correspondiente a cada polígono identificado como entidades territoriales, en hectáreas y calculada geográficamente. m: entidad territorial | G7: Agencia Nacional de Tierras: https://data-agenciadetierras.opendata.arcgis.com/search?tags=ri Periodicidad: mensual Último año con información: septiembre de 2025
A8: Variables de contraste | B8: Proporción territorial de zonas de reserva campesina (ZRC) | C8: - | D8: 2025 | E8: Municipal, distrital y departamental | F8: %ZRC_m= área de ZRC_m/ área total de la entidad territorial_m %ZRC_m: porcentaje de ZRC en relación con el área total de la entidad territorial. Áreas ZRC_m: área correspondiente a los polígonos identificados como ZRC, en hectáreas de acuerdo con la información oficial de la Agencia Nacional de Tierras. Áreas total_m: área correspondiente a cada polígono identificado como entidades territoriales, en hectáreas y calculada geográficamente. m: entidad territorial | G8: Agencia Nacional de Tierras https://data-agenciadetierras.opendata.arcgis.com/datasets/0eca5beb8afe43708622fdd7646cd577_0/explore?location=4.732600%2C-73.819628%2C4.74 Último año con información: septiembre de 2025
A9: Variables de contraste | B9: Índice de Pobreza Multidimensional - IPM | C9: Negativo | D9: 2018 | E9: Municipal, distrital y departamental | F9: El IPM refleja las carencias o privaciones en las condiciones básicas que requieren los hogares de una sociedad para alcanzar el bienestar. Compuesto por cinco dimensiones con el mismo peso y con las siguientes variables: a. Educación: i) Logro Educativo: Si los miembros de 15 años y más tienen menos de 9 años promedio de educación. ii) Alfabetismo: Si al menos un miembro de 15 años y más no sabe leer ni escribir. b. Niñez y juventud: i) Asistencia escolar: Si al menos un miembro de 6 a 16 años no asiste a centro educativo. ii) Rezago escolar: Si al menos un miembro de 7 a 17 años no se encuentra en el grado para la edad iii) Acceso a servicios para el cuidado de la primera infancia: Si al menos un miembro menor de 5 años carece de salud, cuidado y nutrición adecuada. iv) Trabajo infantil: Si al menos un miembro que no pertenece a la población en edad de trabajar –PET–, se encuentra trabajando. c. Trabajo: i) Desempleo de larga duración: Si al menos un miembro del hogar que hace parte de la Población Económicamente Activa –PEA– se encuentra desempleado por más de 12 meses. ii) Empleo formal: Si al menos un miembro del hogar que hace parte de la PEA se encuentra ocupado sin afiliación a pensiones o desempleado. d. Salud i) Aseguramiento en salud: Si al menos un miembro del hogar mayor de 5 años no se encuentra afiliado a salud. ii) Acceso a servicios de salud dada una necesidad: Hogares con al menos una persona que enfrentó un problema de salud que no requirió hospitalización pero que para tratarlo no acudió al lugar adecuado. e. Vivienda i) Acceso a fuentes de agua mejorada: Si un hogar urbano sin servicio público de acueducto; Si un hogar rural se abastece de agua de pozo sin bomba, agua lluvia, río, manantial, carro tanque, aguatero u otra fuente. ii) Eliminación de excretas: Si un hogar urbano está sin servicio público de alcantarillado; Si un hogar rural tiene inodoro sin conexión, bajamar, o no tiene servicio sanitario. ii) Pisos: Si son de tierra. v) Hacinamiento crítico: Si un hogar urbano tiene 3 o más personas por cuarto. Si un hogar rural tiene más de tres personas por cuarto. (Diferencia con el NBI más de 3 personas por cuarto sin diferenciar si es urbano o rural) iv) Paredes exteriores: Si un hogar urbano tiene como material madera burda, tabla, tablón, guadua, otro vegetal, zinc, tela, cartón, desechos o sin paredes; Si un hogar rural tiene como material guadua, otro vegetal, zinc, tela, cartón, desecho o sin paredes. | G9: DANE: https://www.dane.gov.co/index.php/estadisticas-por-tema/pobreza-y-condiciones-de-vida/pobreza-multidimensional Periodicidad: No definida Último año con información: 2018
A10: Variables de contraste | B10: Necesidades Básicas Insatisfechas - NBI | C10: Negativo | D10: 2018 | E10: Municipal, distrital y departamental | F10: La metodología de NBI busca determinar si se encuentran cubiertas las necesidades básicas de la población y cuyas variables son: i) Viviendas inadecuadas ii) Viviendas con hacinamiento crítico iii) Viviendas con servicios inadecuados iv) Viviendas con alta dependencia económica v) Viviendas con niños en edad escolar que no asisten a la escuela. | G10: DANE: https://www.dane.gov.co/index.php/estadisticas-por-tema/pobreza-y-condiciones-de-vida/necesidades-basicas-insatisfechas-nbi Periodicidad: No definida Último año con información: 2018
A11: Variables de contraste | B11: Índice de Incidencia del Conflicto Armado (IICA) | C11: Negativo | D11: 2023 | E11: Municipal, distrital y departamental | F11: El "Índice de Incidencia de Conflicto Armado" es una variable estadística que mide el nivel de conflicto durante un período determinado. Esta variable se basa en la recopilación de los siguientes datos: cultivos de coca, acciones armadas, eventos causados por minas antipersonas, secuestro, desplazamiento forzado, homicidio de líderes sociales y defensores de DD. HH. y homicidio de excombatientes. Con el propósito de facilitar la interpretación y lectura de los resultados del índice, se lleva a cabo un re-escalamiento entre 0 y 1, donde 1 corresponde al valor de mayor incidencia del conflicto. La categorización final se realiza por desviaciones estándar, resultan cinco rangos del IICA, a saber: bajo, medio bajo, medio, alto y muy alto. En este punto es importante aclarar que hay municipios que por la última categorización cuantitativa que se hizo (año 2022) quedaron por encima de 1, pero en la categoría cualitativa igual corresponden a 1 Para efectos visuales, la serie se multiplica por 100, con el fin de que la escala quede establecida de 0 a 100. | G11: DNP- Subdirección de DDHH y Paz Periodicidad: No definida Último año con información: 2023
A12: Variables de contraste | B12: Índice de Riesgo de la Calidad del Agua para Consumo Humano (IRCA) | C12: Negativo | D12: 2024 | E12: Municipal, distrital y departamental | F12: Municipal: Es un indicador que mide el Riesgo de Calidad del Agua (IRCA) a nivel municipal (agregado urbano y rural), el IRCA es "el grado de riesgo de ocurrencia de enfermedades relacionadas con el no cumplimiento de las características físicas, químicas y microbiológicas del agua para consumo humano" (Artículo 12 del Decreto 1575 de 2007). El IRCA toma valores entre 0 y 100% y se establecen niveles de riesgo y acciones de acuerdo al resultado del índice: entre 0% y 5% el agua no presenta riesgo y es apta para el consumo humano; entre 5.1% y 14% el nivel de riesgo es bajo, agua no apta para consumo humano, susceptible de mejoramiento; entre 14.1% y 35% el nivel de riesgo es medio, agua no apta para consumo humano, gestión directa de la persona prestadora; entre 35.1% y 80% el nivel de riesgo es alto, agua no apta para consumo humano, gestión directa de acuerdo a su competencia de la persona prestadora y de los alcaldes y gobernadores respectivos; y finalmente, entre 80.1% y 100% el nivel de riesgo es inviable sanitariamente, agua no apta para consumo humano, gestión directa de acuerdo a su competencia de la persona prestadora, alcaldes, gobernadores y entidades del orden nacional (Artículo 15 de la Resolución MAVDT 2115 de 2007). Departamental: Promedio del nivel municipal | G12: Instituto Nacional de Salud-INS . Dirección de Desarrollo Urbano-DDU (DNP): https://osc.dnp.gov.co/ Periodicidad: Anual Último año con información: 2024
A13: Variables de contraste | B13: Índice de Ciudades Modernas (ICM) | C13: Positivo | D13: 2025 | E13: Municipal, distrital y departamental | F13: El ICM mide del desarrollo integral de ciudades y municipios de todo el país, en seis dimensiones, con 15 subdivisiones (o dominios), y 40 indicadores básicos (variables estandarizadas) ligados a variables que dan cuenta de la evolución de fenómenos particulares. Dimensiones: 1. Equidad e inclusión social: IPM, mortalidad infantil, IRCA, estimación de educación superar, calidad de los colegios 2. Ciencia, tecnología e innovación: velocidad y usuarios de internet, terminales (Portátil + Fijo+ tabletas) por estudiantes, grupos de investigación 3. Sostenibilidad: desastres, desforestación y ecosistemas estratégicos, caudal tratado, sitio y vida útil de disposición final de residuos sólidos 4. Productividad, competitividad y complementariedad: carga y relaciones uni-bidireccionales, valor agregado 5. Gobernanza, participación e instituciones: participación electoral, delitos contra la administración pública, esquemas asociativos, pertenencia a sitios de disposición final de residuos 6. Seguridad: homicidios, lesiones personales , hurtos a residencias, hurtos a personas, hurtos a comercios, extorsiones, víctimas de secuestro *Variables que pertenecen a varias dimensiones: ciudad nodo más cercada, distancias y tiempos de viaje por carretera, estadísticas presupuestales ( i) inversión en gestión de riesgo de desastres, ii) Inversión en gestión del riesgo de desastres, constantes, iii) Inversión total municipal, iv) Inversión total municipal, v) Inversión municipal con recursos propios) Los índices se obtienen por el promedio simple de sus componentes. Todas las variables estandarizadas cuentan con referentes que permiten escalar de 0 a 100. Estos referentes indican niveles aceptables entre los que se puntúa, otro es indicativo de buena condición (se califica con 100), y otro indica una condición no deseable (se califica con cero) | G13: DNP. Dirección de Desarrollo Urbano- Observatorio de Ciudades: https://osc.dnp.gov.co/tematica?dashboard=sc&tematica=icm Periodicidad: Anual Último año con información: 2025
A14: Variables de contraste | B14: Medición del Desempeño Municipal y Departamental (MDM) | C14: Positivo | D14: 2024 | E14: Municipal y distrital | F14: El objetivo es medir el desempeño de las alcaldías, entendido como la capacidad de gestión y de generación de resultados de desarrollo. i) Componente de gestión: incluye las acciones y decisiones que adelanta la administración local que buscan transformar los recursos en un mayor bienestar de la población y desarrollo. Mide las siguientes dimensiones: - Movilización de recursos: Ingresos tributarios y no tributarios per cápita, recaudo por instrumento de OT per cápita, participación de los recursos propios en la inversión - Ejecución de recursos: Ejecución sectores de desarrollo económico, ejecución sectores de desarrollo social, ejecución otros sectores, ejecución de IGPR (regalías) - Gobierno abierto y transparencia: organización de la información, rendición de cuenta, atención al ciudadano - Ordenamiento territorial: Recaudo predial efectivo, uso de instrumentos de recaudo de OT ii) Componente de resultados: mide los elementos constitutivos del bienestar de la población, por medio de las siguientes dimensiones: - Educación: Cobertura neta en transición, cobertura neta en media, puntaje Saber 11 (matemáticas y lenguaje) - Salud: Tasa de mortalidad infantil, cobertura en prevalente, cobertura en afiliación a salud - Seguridad: Tasa de hurtos, tasa de homicidios, tasa de casos de violencia intrafamiliar - Servicios públicos: cobertura de energía eléctrica rural, cobertura de acueducto y alcantarillado, penetración de internet y banda ancha | G14: MDM- DNP: https://portalterritorial.dnp.gov.co/AdmInfoTerritorial/MenuInfoTerrEstMDM Periodicidad: Anual Último año con información: 2024
A15: Variables de contraste | B15: Medición del Desempeño Departamental (MDD) | C15: Positivo | D15: 2024 | E15: Departamental | F15: El objetivo es medir el desempeño de las gobernaciones, entendido como: la capacidad de gestión y de generación de resultados de desarrollo. i) Componente de gestión, mide las siguientes dimensiones: - Movilización de recursos: Ingresos tributarios y no tributarios per cápita, participación de los recursos propios, dependencia de las transferencias - Ejecución de recursos: Ejecución sectores de desarrollo económico, Ejecución sectores de desarrollo social, Ejecución otros sectores, Ejecución de IGPR (ejecución de recursos de los proyectos de regalías a cargo de la gobernación) - Gobierno abierto y transparencia: gobierno digital, integridad, participación ciudadana, servicio al ciudadano, acceso a la información - Planeación estratégica: talento humano, planeación institucional, seguimiento y evaluación. ii) Componente de resultados, mide las siguientes dimensiones: - Educación: Cobertura neta en transición, cobertura neta en media, puntaje Saber 11 (matemáticas y lenguaje) - Salud: Tasa de mortalidad infantil, cobertura en prevalente, cobertura en afiliación a salud - Seguridad: Tasa de hurtos, tasa de homicidios, tasa de casos de violencia intrafamiliar - Servicios públicos: cobertura de energía eléctrica rural, cobertura de acueducto y alcantarillado, penetración de internet y banda ancha - Niñez y juventud: cuidado infancia, trabajo infantil - Medio ambiente: Tasa de deforestación, emisiones CO2, gestión de desastres, residuos en relleno - Trabajo: tasa de desempleo, informalidad laboral, pobreza monetaria | G15: MDD- DNP: https://portalterritorial.dnp.gov.co/AdmInfoTerritorial/MenuInfoTerrEstMDM Periodicidad: Anual Último año con información: 2024
A16: Variables de contraste | B16: Ingresos totales e ingresos tributarios | C16: Positivo | D16: 2024 | E16: Municipal, distrital y departamental | F16: Con esta variable de contraste se quiere evidenciar la capacidad financiera de las entidades territoriales para el cumplimiento de sus funciones y competencias, principalmente para la provisión de bienes y servicios público. | G16: Operaciones efectivas de caja- DNP Periodicidad: Anual Último año con información: 2024

Sheet Contrastes_Mun1
A1: ANÁLISIS DE CONTRASTE MUNICIPIOS - VARIABLES CATEGÓRICAS
A2: Categorías 617 de 2000
A4: Tipología | B4: ESP | C4: 1 | D4: 2 | E4: 3 | F4: 4 | G4: 5 | H4: 6 | I4: N.D. | J4: Total
A5: Bogotá | B5: =+COUNTIFS(Municipios!$Y:$Y,Contrastes_Mun1!$A5,Municipios!$BC:$BC,Contrastes_Mun1!B$4) -> 1 | C5: =+COUNTIFS(Municipios!$Y:$Y,Contrastes_Mun1!$A5,Municipios!$BC:$BC,Contrastes_Mun1!C$4) -> 0 | D5: =+COUNTIFS(Municipios!$Y:$Y,Contrastes_Mun1!$A5,Municipios!$BC:$BC,Contrastes_Mun1!D$4) -> 0 | E5: =+COUNTIFS(Municipios!$Y:$Y,Contrastes_Mun1!$A5,Municipios!$BC:$BC,Contrastes_Mun1!E$4) -> 0 | F5: =+COUNTIFS(Municipios!$Y:$Y,Contrastes_Mun1!$A5,Municipios!$BC:$BC,Contrastes_Mun1!F$4) -> 0 | G5: =+COUNTIFS(Municipios!$Y:$Y,Contrastes_Mun1!$A5,Municipios!$BC:$BC,Contrastes_Mun1!G$4) -> 0 | H5: =+COUNTIFS(Municipios!$Y:$Y,Contrastes_Mun1!$A5,Municipios!$BC:$BC,Contrastes_Mun1!H$4) -> 0 | I5: =+COUNTIFS(Municipios!$Y:$Y,Contrastes_Mun1!$A5,Municipios!$BC:$BC,Contrastes_Mun1!I$4) -> 0 | J5: =+SUM(B5:I5) -> 1
A6: Ciudades grandes | B6: =+COUNTIFS(Municipios!$Y:$Y,Contrastes_Mun1!$A6,Municipios!$BC:$BC,Contrastes_Mun1!B$4) -> 5 | C6: =+COUNTIFS(Municipios!$Y:$Y,Contrastes_Mun1!$A6,Municipios!$BC:$BC,Contrastes_Mun1!C$4) -> 0 | D6: =+COUNTIFS(Municipios!$Y:$Y,Contrastes_Mun1!$A6,Municipios!$BC:$BC,Contrastes_Mun1!D$4) -> 0 | E6: =+COUNTIFS(Municipios!$Y:$Y,Contrastes_Mun1!$A6,Municipios!$BC:$BC,Contrastes_Mun1!E$4) -> 0 | F6: =+COUNTIFS(Municipios!$Y:$Y,Contrastes_Mun1!$A6,Municipios!$BC:$BC,Contrastes_Mun1!F$4) -> 0 | G6: =+COUNTIFS(Municipios!$Y:$Y,Contrastes_Mun1!$A6,Municipios!$BC:$BC,Contrastes_Mun1!G$4) -> 0 | H6: =+COUNTIFS(Municipios!$Y:$Y,Contrastes_Mun1!$A6,Municipios!$BC:$BC,Contrastes_Mun1!H$4) -> 0 | I6: =+COUNTIFS(Municipios!$Y:$Y,Contrastes_Mun1!$A6,Municipios!$BC:$BC,Contrastes_Mun1!I$4) -> 0 | J6: =+SUM(B6:I6) -> 5
A7: 1 | B7: =+COUNTIFS(Municipios!$Y:$Y,Contrastes_Mun1!$A7,Municipios!$BC:$BC,Contrastes_Mun1!B$4) -> 0 | C7: =+COUNTIFS(Municipios!$Y:$Y,Contrastes_Mun1!$A7,Municipios!$BC:$BC,Contrastes_Mun1!C$4) -> 18 | D7: =+COUNTIFS(Municipios!$Y:$Y,Contrastes_Mun1!$A7,Municipios!$BC:$BC,Contrastes_Mun1!D$4) -> 14 | E7: =+COUNTIFS(Municipios!$Y:$Y,Contrastes_Mun1!$A7,Municipios!$BC:$BC,Contrastes_Mun1!E$4) -> 5 | F7: =+COUNTIFS(Municipios!$Y:$Y,Contrastes_Mun1!$A7,Municipios!$BC:$BC,Contrastes_Mun1!F$4) -> 3 | G7: =+COUNTIFS(Municipios!$Y:$Y,Contrastes_Mun1!$A7,Municipios!$BC:$BC,Contrastes_Mun1!G$4) -> 4 | H7: =+COUNTIFS(Municipios!$Y:$Y,Contrastes_Mun1!$A7,Municipios!$BC:$BC,Contrastes_Mun1!H$4) -> 5 | I7: =+COUNTIFS(Municipios!$Y:$Y,Contrastes_Mun1!$A7,Municipios!$BC:$BC,Contrastes_Mun1!I$4) -> 0 | J7: =+SUM(B7:I7) -> 49
A8: 2 | B8: =+COUNTIFS(Municipios!$Y:$Y,Contrastes_Mun1!$A8,Municipios!$BC:$BC,Contrastes_Mun1!B$4) -> 0 | C8: =+COUNTIFS(Municipios!$Y:$Y,Contrastes_Mun1!$A8,Municipios!$BC:$BC,Contrastes_Mun1!C$4) -> 9 | D8: =+COUNTIFS(Municipios!$Y:$Y,Contrastes_Mun1!$A8,Municipios!$BC:$BC,Contrastes_Mun1!D$4) -> 10 | E8: =+COUNTIFS(Municipios!$Y:$Y,Contrastes_Mun1!$A8,Municipios!$BC:$BC,Contrastes_Mun1!E$4) -> 10 | F8: =+COUNTIFS(Municipios!$Y:$Y,Contrastes_Mun1!$A8,Municipios!$BC:$BC,Contrastes_Mun1!F$4) -> 9 | G8: =+COUNTIFS(Municipios!$Y:$Y,Contrastes_Mun1!$A8,Municipios!$BC:$BC,Contrastes_Mun1!G$4) -> 21 | H8: =+COUNTIFS(Municipios!$Y:$Y,Contrastes_Mun1!$A8,Municipios!$BC:$BC,Contrastes_Mun1!H$4) -> 94 | I8: =+COUNTIFS(Municipios!$Y:$Y,Contrastes_Mun1!$A8,Municipios!$BC:$BC,Contrastes_Mun1!I$4) -> 0 | J8: =+SUM(B8:I8) -> 153
A9: 3 | B9: =+COUNTIFS(Municipios!$Y:$Y,Contrastes_Mun1!$A9,Municipios!$BC:$BC,Contrastes_Mun1!B$4) -> 0 | C9: =+COUNTIFS(Municipios!$Y:$Y,Contrastes_Mun1!$A9,Municipios!$BC:$BC,Contrastes_Mun1!C$4) -> 0 | D9: =+COUNTIFS(Municipios!$Y:$Y,Contrastes_Mun1!$A9,Municipios!$BC:$BC,Contrastes_Mun1!D$4) -> 2 | E9: =+COUNTIFS(Municipios!$Y:$Y,Contrastes_Mun1!$A9,Municipios!$BC:$BC,Contrastes_Mun1!E$4) -> 2 | F9: =+COUNTIFS(Municipios!$Y:$Y,Contrastes_Mun1!$A9,Municipios!$BC:$BC,Contrastes_Mun1!F$4) -> 7 | G9: =+COUNTIFS(Municipios!$Y:$Y,Contrastes_Mun1!$A9,Municipios!$BC:$BC,Contrastes_Mun1!G$4) -> 13 | H9: =+COUNTIFS(Municipios!$Y:$Y,Contrastes_Mun1!$A9,Municipios!$BC:$BC,Contrastes_Mun1!H$4) -> 344 | I9: =+COUNTIFS(Municipios!$Y:$Y,Contrastes_Mun1!$A9,Municipios!$BC:$BC,Contrastes_Mun1!I$4) -> 0 | J9: =+SUM(B9:I9) -> 368
A10: 4 | B10: =+COUNTIFS(Municipios!$Y:$Y,Contrastes_Mun1!$A10,Municipios!$BC:$BC,Contrastes_Mun1!B$4) -> 0 | C10: =+COUNTIFS(Municipios!$Y:$Y,Contrastes_Mun1!$A10,Municipios!$BC:$BC,Contrastes_Mun1!C$4) -> 0 | D10: =+COUNTIFS(Municipios!$Y:$Y,Contrastes_Mun1!$A10,Municipios!$BC:$BC,Contrastes_Mun1!D$4) -> 2 | E10: =+COUNTIFS(Municipios!$Y:$Y,Contrastes_Mun1!$A10,Municipios!$BC:$BC,Contrastes_Mun1!E$4) -> 0 | F10: =+COUNTIFS(Municipios!$Y:$Y,Contrastes_Mun1!$A10,Municipios!$BC:$BC,Contrastes_Mun1!F$4) -> 3 | G10: =+COUNTIFS(Municipios!$Y:$Y,Contrastes_Mun1!$A10,Municipios!$BC:$BC,Contrastes_Mun1!G$4) -> 8 | H10: =+COUNTIFS(Municipios!$Y:$Y,Contrastes_Mun1!$A10,Municipios!$BC:$BC,Contrastes_Mun1!H$4) -> 395 | I10: =+COUNTIFS(Municipios!$Y:$Y,Contrastes_Mun1!$A10,Municipios!$BC:$BC,Contrastes_Mun1!I$4) -> 1 | J10: =+SUM(B10:I10) -> 409
A11: 5 | B11: =+COUNTIFS(Municipios!$Y:$Y,Contrastes_Mun1!$A11,Municipios!$BC:$BC,Contrastes_Mun1!B$4) -> 0 | C11: =+COUNTIFS(Municipios!$Y:$Y,Contrastes_Mun1!$A11,Municipios!$BC:$BC,Contrastes_Mun1!C$4) -> 0 | D11: =+COUNTIFS(Municipios!$Y:$Y,Contrastes_Mun1!$A11,Municipios!$BC:$BC,Contrastes_Mun1!D$4) -> 1 | E11: =+COUNTIFS(Municipios!$Y:$Y,Contrastes_Mun1!$A11,Municipios!$BC:$BC,Contrastes_Mun1!E$4) -> 0 | F11: =+COUNTIFS(Municipios!$Y:$Y,Contrastes_Mun1!$A11,Municipios!$BC:$BC,Contrastes_Mun1!F$4) -> 1 | G11: =+COUNTIFS(Municipios!$Y:$Y,Contrastes_Mun1!$A11,Municipios!$BC:$BC,Contrastes_Mun1!G$4) -> 2 | H11: =+COUNTIFS(Municipios!$Y:$Y,Contrastes_Mun1!$A11,Municipios!$BC:$BC,Contrastes_Mun1!H$4) -> 114 | I11: =+COUNTIFS(Municipios!$Y:$Y,Contrastes_Mun1!$A11,Municipios!$BC:$BC,Contrastes_Mun1!I$4) -> 0 | J11: =+SUM(B11:I11) -> 118
A12: Total | B12: =+SUM(B5:B11) -> 6 | C12: =+SUM(C5:C11) -> 27 | D12: =+SUM(D5:D11) -> 29 | E12: =+SUM(E5:E11) -> 17 | F12: =+SUM(F5:F11) -> 23 | G12: =+SUM(G5:G11) -> 48 | H12: =+SUM(H5:H11) -> 952 | I12: =+SUM(I5:I11) -> 1 | J12: =+SUM(B12:I12) -> 1103
H13: =H12/J12 -> 0.86310063
A14: Municipios PDET
A16: Tipología | B16: 0 | C16: 1 | D16: Total
A17: Bogotá | B17: =+COUNTIFS(Municipios!$Y:$Y,Contrastes_Mun1!$A17,Municipios!$AZ:$AZ,Contrastes_Mun1!B$16) -> 1 | C17: =+COUNTIFS(Municipios!$Y:$Y,Contrastes_Mun1!$A17,Municipios!$AZ:$AZ,Contrastes_Mun1!C$16) -> 0 | D17: =+SUM(B17:C17) -> 1
A18: Ciudades grandes | B18: =+COUNTIFS(Municipios!$Y:$Y,Contrastes_Mun1!$A18,Municipios!$AZ:$AZ,Contrastes_Mun1!B$16) -> 5 | C18: =+COUNTIFS(Municipios!$Y:$Y,Contrastes_Mun1!$A18,Municipios!$AZ:$AZ,Contrastes_Mun1!C$16) -> 0 | D18: =+SUM(B18:C18) -> 5
A19: 1 | B19: =+COUNTIFS(Municipios!$Y:$Y,Contrastes_Mun1!$A19,Municipios!$AZ:$AZ,Contrastes_Mun1!B$16) -> 49 | C19: =+COUNTIFS(Municipios!$Y:$Y,Contrastes_Mun1!$A19,Municipios!$AZ:$AZ,Contrastes_Mun1!C$16) -> 0 | D19: =+SUM(B19:C19) -> 49
A20: 2 | B20: =+COUNTIFS(Municipios!$Y:$Y,Contrastes_Mun1!$A20,Municipios!$AZ:$AZ,Contrastes_Mun1!B$16) -> 144 | C20: =+COUNTIFS(Municipios!$Y:$Y,Contrastes_Mun1!$A20,Municipios!$AZ:$AZ,Contrastes_Mun1!C$16) -> 9 | D20: =+SUM(B20:C20) -> 153 | E20: =+C20/$C$24 -> 0.052941176
A21: 3 | B21: =+COUNTIFS(Municipios!$Y:$Y,Contrastes_Mun1!$A21,Municipios!$AZ:$AZ,Contrastes_Mun1!B$16) -> 331 | C21: =+COUNTIFS(Municipios!$Y:$Y,Contrastes_Mun1!$A21,Municipios!$AZ:$AZ,Contrastes_Mun1!C$16) -> 37 | D21: =+SUM(B21:C21) -> 368 | E21: =+C21/$C$24 -> 0.21764706
A22: 4 | B22: =+COUNTIFS(Municipios!$Y:$Y,Contrastes_Mun1!$A22,Municipios!$AZ:$AZ,Contrastes_Mun1!B$16) -> 327 | C22: =+COUNTIFS(Municipios!$Y:$Y,Contrastes_Mun1!$A22,Municipios!$AZ:$AZ,Contrastes_Mun1!C$16) -> 82 | D22: =+SUM(B22:C22) -> 409 | E22: =+C22/$C$24 -> 0.48235294
A23: 5 | B23: =+COUNTIFS(Municipios!$Y:$Y,Contrastes_Mun1!$A23,Municipios!$AZ:$AZ,Contrastes_Mun1!B$16) -> 76 | C23: =+COUNTIFS(Municipios!$Y:$Y,Contrastes_Mun1!$A23,Municipios!$AZ:$AZ,Contrastes_Mun1!C$16) -> 42 | D23: =+SUM(B23:C23) -> 118 | E23: =+C23/$C$24 -> 0.24705882
A24: Total | B24: =+SUM(B17:B23) -> 933 | C24: =+SUM(C17:C23) -> 170 | D24: =+SUM(B24:C24) -> 1103
A26: Municipios ZOMAC
A28: Tipología | B28: 0 | C28: 1 | D28: Total
A29: Bogotá | B29: =+COUNTIFS(Municipios!$Y:$Y,Contrastes_Mun1!$A29,Municipios!$BA:$BA,Contrastes_Mun1!B$28) -> 1 | C29: =+COUNTIFS(Municipios!$Y:$Y,Contrastes_Mun1!$A29,Municipios!$BA:$BA,Contrastes_Mun1!C$28) -> 0 | D29: =+SUM(B29:C29) -> 1
A30: Ciudades grandes | B30: =+COUNTIFS(Municipios!$Y:$Y,Contrastes_Mun1!$A30,Municipios!$BA:$BA,Contrastes_Mun1!B$28) -> 5 | C30: =+COUNTIFS(Municipios!$Y:$Y,Contrastes_Mun1!$A30,Municipios!$BA:$BA,Contrastes_Mun1!C$28) -> 0 | D30: =+SUM(B30:C30) -> 5
A31: 1 | B31: =+COUNTIFS(Municipios!$Y:$Y,Contrastes_Mun1!$A31,Municipios!$BA:$BA,Contrastes_Mun1!B$28) -> 49 | C31: =+COUNTIFS(Municipios!$Y:$Y,Contrastes_Mun1!$A31,Municipios!$BA:$BA,Contrastes_Mun1!C$28) -> 0 | D31: =+SUM(B31:C31) -> 49 | E31: =+C31/$C$36 -> 0
A32: 2 | B32: =+COUNTIFS(Municipios!$Y:$Y,Contrastes_Mun1!$A32,Municipios!$BA:$BA,Contrastes_Mun1!B$28) -> 136 | C32: =+COUNTIFS(Municipios!$Y:$Y,Contrastes_Mun1!$A32,Municipios!$BA:$BA,Contrastes_Mun1!C$28) -> 17 | D32: =+SUM(B32:C32) -> 153 | E32: =+C32/$C$36 -> 0.049418605
A33: 3 | B33: =+COUNTIFS(Municipios!$Y:$Y,Contrastes_Mun1!$A33,Municipios!$BA:$BA,Contrastes_Mun1!B$28) -> 280 | C33: =+COUNTIFS(Municipios!$Y:$Y,Contrastes_Mun1!$A33,Municipios!$BA:$BA,Contrastes_Mun1!C$28) -> 88 | D33: =+SUM(B33:C33) -> 368 | E33: =+C33/$C$36 -> 0.25581395
A34: 4 | B34: =+COUNTIFS(Municipios!$Y:$Y,Contrastes_Mun1!$A34,Municipios!$BA:$BA,Contrastes_Mun1!B$28) -> 244 | C34: =+COUNTIFS(Municipios!$Y:$Y,Contrastes_Mun1!$A34,Municipios!$BA:$BA,Contrastes_Mun1!C$28) -> 165 | D34: =+SUM(B34:C34) -> 409 | E34: =+C34/$C$36 -> 0.47965116
A35: 5 | B35: =+COUNTIFS(Municipios!$Y:$Y,Contrastes_Mun1!$A35,Municipios!$BA:$BA,Contrastes_Mun1!B$28) -> 44 | C35: =+COUNTIFS(Municipios!$Y:$Y,Contrastes_Mun1!$A35,Municipios!$BA:$BA,Contrastes_Mun1!C$28) -> 74 | D35: =+SUM(B35:C35) -> 118 | E35: =+C35/$C$36 -> 0.21511628
A36: Total | B36: =+SUM(B29:B35) -> 759 | C36: =+SUM(C29:C35) -> 344 | D36: =+SUM(B36:C36) -> 1103
A38: Rangos IRCA
A41: Tipología | B41: Alto | C41: Bajo | D41: Inviable | E41: Medio | F41: Sin información | G41: Sin riesgo | H41: Inviable sanitariamente | I41: Total
A42: Bogotá | B42: =+COUNTIFS(Municipios!$Y:$Y,Contrastes_Mun1!$A42,Municipios!$BK:$BK,Contrastes_Mun1!B$41) -> 0 | C42: =+COUNTIFS(Municipios!$Y:$Y,Contrastes_Mun1!$A42,Municipios!$BK:$BK,Contrastes_Mun1!C$41) -> 0 | D42: =+COUNTIFS(Municipios!$Y:$Y,Contrastes_Mun1!$A42,Municipios!$BK:$BK,Contrastes_Mun1!D$41) -> 0 | E42: =+COUNTIFS(Municipios!$Y:$Y,Contrastes_Mun1!$A42,Municipios!$BK:$BK,Contrastes_Mun1!E$41) -> 0 | F42: =+COUNTIFS(Municipios!$Y:$Y,Contrastes_Mun1!$A42,Municipios!$BK:$BK,Contrastes_Mun1!F$41) -> 0 | G42: =+COUNTIFS(Municipios!$Y:$Y,Contrastes_Mun1!$A42,Municipios!$BK:$BK,Contrastes_Mun1!G$41) -> 1 | H42: =+COUNTIFS(Municipios!$Y:$Y,Contrastes_Mun1!$A42,Municipios!$BK:$BK,Contrastes_Mun1!H$41) -> 0 | I42: =+SUM(B42:H42) -> 1
A43: Ciudades grandes | B43: =+COUNTIFS(Municipios!$Y:$Y,Contrastes_Mun1!$A43,Municipios!$BK:$BK,Contrastes_Mun1!B$41) -> 0 | C43: =+COUNTIFS(Municipios!$Y:$Y,Contrastes_Mun1!$A43,Municipios!$BK:$BK,Contrastes_Mun1!C$41) -> 0 | D43: =+COUNTIFS(Municipios!$Y:$Y,Contrastes_Mun1!$A43,Municipios!$BK:$BK,Contrastes_Mun1!D$41) -> 0 | E43: =+COUNTIFS(Municipios!$Y:$Y,Contrastes_Mun1!$A43,Municipios!$BK:$BK,Contrastes_Mun1!E$41) -> 0 | F43: =+COUNTIFS(Municipios!$Y:$Y,Contrastes_Mun1!$A43,Municipios!$BK:$BK,Contrastes_Mun1!F$41) -> 0 | G43: =+COUNTIFS(Municipios!$Y:$Y,Contrastes_Mun1!$A43,Municipios!$BK:$BK,Contrastes_Mun1!G$41) -> 5 | H43: =+COUNTIFS(Municipios!$Y:$Y,Contrastes_Mun1!$A43,Municipios!$BK:$BK,Contrastes_Mun1!H$41) -> 0 | I43: =+SUM(B43:H43) -> 5
A44: 1 | B44: =+COUNTIFS(Municipios!$Y:$Y,Contrastes_Mun1!$A44,Municipios!$BK:$BK,Contrastes_Mun1!B$41) -> 0 | C44: =+COUNTIFS(Municipios!$Y:$Y,Contrastes_Mun1!$A44,Municipios!$BK:$BK,Contrastes_Mun1!C$41) -> 11 | D44: =+COUNTIFS(Municipios!$Y:$Y,Contrastes_Mun1!$A44,Municipios!$BK:$BK,Contrastes_Mun1!D$41) -> 0 | E44: =+COUNTIFS(Municipios!$Y:$Y,Contrastes_Mun1!$A44,Municipios!$BK:$BK,Contrastes_Mun1!E$41) -> 0 | F44: =+COUNTIFS(Municipios!$Y:$Y,Contrastes_Mun1!$A44,Municipios!$BK:$BK,Contrastes_Mun1!F$41) -> 0 | G44: =+COUNTIFS(Municipios!$Y:$Y,Contrastes_Mun1!$A44,Municipios!$BK:$BK,Contrastes_Mun1!G$41) -> 38 | H44: =+COUNTIFS(Municipios!$Y:$Y,Contrastes_Mun1!$A44,Municipios!$BK:$BK,Contrastes_Mun1!H$41) -> 0 | I44: =+SUM(B44:H44) -> 49
A45: 2 | B45: =+COUNTIFS(Municipios!$Y:$Y,Contrastes_Mun1!$A45,Municipios!$BK:$BK,Contrastes_Mun1!B$41) -> 11 | C45: =+COUNTIFS(Municipios!$Y:$Y,Contrastes_Mun1!$A45,Municipios!$BK:$BK,Contrastes_Mun1!C$41) -> 44 | D45: =+COUNTIFS(Municipios!$Y:$Y,Contrastes_Mun1!$A45,Municipios!$BK:$BK,Contrastes_Mun1!D$41) -> 0 | E45: =+COUNTIFS(Municipios!$Y:$Y,Contrastes_Mun1!$A45,Municipios!$BK:$BK,Contrastes_Mun1!E$41) -> 32 | F45: =+COUNTIFS(Municipios!$Y:$Y,Contrastes_Mun1!$A45,Municipios!$BK:$BK,Contrastes_Mun1!F$41) -> 3 | G45: =+COUNTIFS(Municipios!$Y:$Y,Contrastes_Mun1!$A45,Municipios!$BK:$BK,Contrastes_Mun1!G$41) -> 63 | H45: =+COUNTIFS(Municipios!$Y:$Y,Contrastes_Mun1!$A45,Municipios!$BK:$BK,Contrastes_Mun1!H$41) -> 0 | I45: =+SUM(B45:H45) -> 153
